Workbook
Name \0: #REF!
Name \0: #REF!
Name \0: #REF!
Name \0: #REF!
Name \a: #REF!
Name \a: #REF!
Name \a: #REF!
Name \C: #REF!
Name \C: #REF!
Name \kl: #REF!
Name \kl: #REF!
Name \l: #REF!
Name \l: #REF!
Name \p: #REF!
Name \p: #REF!
Name ______________________________________________iv66666: #REF!
Name _____________________________________________iv66666: #REF!
Name ____________________________________________iv66666: #REF!
Name ___________________________________________iv66666: #REF!
Name __________________________________________iv66666: #REF!
Name __________________________________________iv66666: #REF!
Name __________________________________________iv66666: #REF!
Name _________________________________________aj1: #REF!
Name _________________________________________b1: #REF!
Name _________________________________________b1: #REF!
Name _________________________________________B100000: #REF!
Name _________________________________________B100000: #REF!
Name _________________________________________bol1: #REF!
Name _________________________________________can430: 40.73
Name _________________________________________can435: 43.3
Name _________________________________________iv66666: #REF!
Name _________________________________________sdb2: #REF!
Name ________________________________________aj1: #REF!
Name ________________________________________aj1: #REF!
Name ________________________________________b1: #REF!
Name ________________________________________b1: #REF!
Name ________________________________________B100000: #REF!
Name ________________________________________bol1: #REF!
Name ________________________________________can430: 40.73
Name ________________________________________can435: 43.3
Name ________________________________________iv66666: #REF!
Name ________________________________________sdb2: #REF!
Name _______________________________________aj1: #REF!
Name _______________________________________aj1: #REF!
Name _______________________________________b1: #REF!
Name _______________________________________b1: #REF!
Name _______________________________________B100000: #REF!
Name _______________________________________bol1: #REF!
Name _______________________________________can430: 40.73
Name _______________________________________can435: 43.3
Name _______________________________________iv66666: #REF!
Name _______________________________________iv66666: #REF!
Name _______________________________________iv66666: #REF!
Name _______________________________________sdb2: #REF!
Name ______________________________________aj1: #REF!
Name ______________________________________aj1: #REF!
Name ______________________________________b1: #REF!
Name ______________________________________b1: #REF!
Name ______________________________________B100000: #REF!
Name ______________________________________bol1: #REF!

Sheet Abstract
A1: PROJECT : PANNIYANKARA LAND
A2: RETAINING WALL & FOOTING
B5: S.No | C5: Description | D5: Nos | E5: Footing Quantity | I5: Retaining wall quantity
E6: PCC | F6: Concrete | G6: Shuttering | H6: Reinforcement | I6: Concrete | J6: Shuttering | K6: Reinforcement | N6: Length
C7: External Retaining Wall
B8: 1 | C8: SECTION-1-1 | D8: 1 | E8: =$D8*'RW Footing'!$S$31 -> 22.1949 | F8: =$D8*'RW Footing'!$Q$31 -> 105.465 | G8: =$D8*'RW Footing'!$R$31 -> 70.585476 | H8: =$D8*'RW Footing'!$P$31/1000 -> 0 | I8: =D8*'Retaining wall'!I33 -> 88.58617 | J8: =D8*'Retaining wall'!J33 -> 507.46669 | K8: =$D8*'Retaining wall'!S33/1000 -> 0 | L8: =H8*1000/F8 -> 0 | M8: =K8*1000/I8 -> 0 | N8: 70.306484
B9: 2 | C9: SECTION 1A-1A | D9: 1 | E9: =$D9*'RW Footing'!#REF! -> #REF! | F9: =$D9*'RW Footing'!#REF! -> #REF! | G9: =$D9*'RW Footing'!#REF! -> #REF! | H9: =$D9*'RW Footing'!#REF!/1000 -> #REF! | I9: ='Retaining wall'!I34 -> 4.476605 | J9: =D9*'Retaining wall'!J34 -> 25.5806 | K9: =$D9*'Retaining wall'!S34/1000 -> 0 | L9: =H9*1000/F9 -> #REF! | M9: =K9*1000/I9 -> 0 | N9: 5.561
B10: 3 | C10: SECTION 2A-2A | D10: 1 | E10: =$D10*'RW Footing'!#REF! -> #REF! | F10: =$D10*'RW Footing'!#REF! -> #REF! | G10: =$D10*'RW Footing'!#REF! -> #REF! | H10: =$D10*'RW Footing'!#REF!/1000 -> #REF! | I10: ='Retaining wall'!I35 -> 12.47958 | J10: ='Retaining wall'!J35 -> 83.1972 | K10: =$D10*'Retaining wall'!S35/1000 -> 0 | L10: =H10*1000/F10 -> #REF! | M10: =K10*1000/I10 -> 0 | N10: 7.298
B11: 4 | C11: SECTION 2B-2B | D11: 1 | E11: =$D11*'RW Footing'!#REF! -> #REF! | F11: =$D11*'RW Footing'!#REF! -> #REF! | G11: =$D11*'RW Footing'!#REF! -> #REF! | H11: =$D11*'RW Footing'!#REF!/1000 -> #REF! | I11: ='Retaining wall'!I36 -> 8.6856 | J11: ='Retaining wall'!J36 -> 57.904 | K11: =$D11*'Retaining wall'!S36/1000 -> 0 | L11: =H11*1000/F11 -> #REF! | M11: =K11*1000/I11 -> 0 | N11: 6.16
B12: 5 | C12: SECTION 7-7 | D12: 1 | E12: =$D12*'RW Footing'!#REF! -> #REF! | F12: =$D12*'RW Footing'!#REF! -> #REF! | G12: =$D12*'RW Footing'!#REF! -> #REF! | H12: =$D12*'RW Footing'!#REF!/1000 -> #REF! | I12: ='Retaining wall'!I37 -> 9.9414 | J12: ='Retaining wall'!J37 -> 66.276 | K12: =$D12*'Retaining wall'!S37/1000 -> 0 | L12: =H12*1000/F12 -> #REF! | M12: =K12*1000/I12 -> 0 | N12: =5.925+1.965 -> 7.89
B13: 6 | C13: SECTION 8-8 | D13: 1 | E13: =$D13*'RW Footing'!#REF! -> #REF! | F13: =$D13*'RW Footing'!#REF! -> #REF! | G13: =$D13*'RW Footing'!#REF! -> #REF! | H13: =$D13*'RW Footing'!#REF!/1000 -> #REF! | I13: =$D13*SUM('Retaining wall'!I38:I38) -> 6.8991 | J13: =$D13*SUM('Retaining wall'!J38:J38) -> 45.994 | K13: =$D13*'Retaining wall'!S38/1000 -> 0 | L13: =H13*1000/F13 -> #REF! | M13: =K13*1000/I13 -> 0 | N13: 7.54
B14: 7 | C14: SECTION 9-9 | D14: 1 | E14: =$D14*'RW Footing'!#REF! -> #REF! | F14: =$D14*'RW Footing'!#REF! -> #REF! | G14: =$D14*'RW Footing'!#REF! -> #REF! | H14: =$D14*'RW Footing'!#REF!/1000 -> #REF! | I14: ='Retaining wall'!I39 -> 17.6352 | J14: ='Retaining wall'!J39 -> 117.568 | K14: =$D14*'Retaining wall'!S39/1000 -> 0 | L14: =H14*1000/F14 -> #REF! | M14: =K14*1000/I14 -> 0 | N14: 13.36
B15: 8 | C15: SECTION 10-10 | D15: 1 | E15: =$D15*'RW Footing'!#REF! -> #REF! | F15: =$D15*'RW Footing'!#REF! -> #REF! | G15: =$D15*'RW Footing'!#REF! -> #REF! | H15: =$D15*'RW Footing'!#REF!/1000 -> #REF! | I15: ='Retaining wall'!I40 -> 3.7845 | J15: ='Retaining wall'!J40 -> 25.23 | K15: =$D15*'Retaining wall'!S40/1000 -> 0 | L15: =H15*1000/F15 -> #REF! | M15: =K15*1000/I15 -> 0 | N15: 2.9
B16: 9 | C16: SECTION 11-11 | D16: 1 | E16: =$D16*'RW Footing'!#REF! -> #REF! | F16: =$D16*'RW Footing'!#REF! -> #REF! | G16: =$D16*'RW Footing'!#REF! -> #REF! | H16: =$D16*'RW Footing'!#REF!/1000 -> #REF! | I16: ='Retaining wall'!I41 -> 76.82724 | J16: ='Retaining wall'!J41 -> 512.1816 | K16: =$D16*'Retaining wall'!S41/1000 -> 0 | L16: =H16*1000/F16 -> #REF! | M16: =K16*1000/I16 -> 0 | N16: =47.174+0.9+3.4+9.5 -> 60.974
C17: Internal Retaining Wall
B18: 10 | C18: SECTION 2-2 | D18: 1 | E18: =$D18*'RW Footing'!#REF! -> #REF! | F18: =$D18*'RW Footing'!#REF! -> #REF! | G18: =$D18*'RW Footing'!#REF! -> #REF! | H18: =$D18*'RW Footing'!#REF!/1000 -> #REF! | I18: ='Retaining wall'!I42 -> 87.039 | J18: ='Retaining wall'!J42 -> 580.26 | K18: =$D18*'Retaining wall'!S42/1000 -> 0 | L18: =H18*1000/F18 -> #REF! | M18: =K18*1000/I18 -> 0 | N18: 50.9
B19: 10 | C19: SECTION 3-3 | D19: 1 | E19: =$D19*'RW Footing'!#REF! -> #REF! | F19: =$D19*'RW Footing'!#REF! -> #REF! | G19: =$D19*'RW Footing'!#REF! -> #REF! | H19: =$D19*'RW Footing'!#REF!/1000 -> #REF! | I19: ='Retaining wall'!I43 -> 13.5 | J19: ='Retaining wall'!J43 -> 90 | K19: =$D19*'Retaining wall'!S43/1000 -> 0 | L19: =H19*1000/F19 -> #REF! | M19: =K19*1000/I19 -> 0 | N19: 10
B20: 10 | C20: SECTION 4-4 | D20: 1 | E20: =$D20*'RW Footing'!#REF! -> #REF! | F20: =$D20*'RW Footing'!#REF! -> #REF! | G20: =$D20*'RW Footing'!#REF! -> #REF! | H20: =$D20*'RW Footing'!#REF!/1000 -> #REF! | I20: ='Retaining wall'!I44 -> 9.45 | J20: ='Retaining wall'!J44 -> 63 | K20: =$D20*'Retaining wall'!#REF!/1000 -> #REF! | L20: =H20*1000/F20 -> #REF! | M20: =K20*1000/I20 -> #REF! | N20: 9
B21: 10 | C21: SECTION 5-5 | D21: 1 | E21: =$D21*'RW Footing'!#REF! -> #REF! | F21: =$D21*'RW Footing'!#REF! -> #REF! | G21: =$D21*'RW Footing'!#REF! -> #REF! | H21: =$D21*'RW Footing'!#REF!/1000 -> #REF! | I21: ='Retaining wall'!I45 -> 3.096 | J21: ='Retaining wall'!J45 -> 30.96 | K21: =$D21*'Retaining wall'!#REF!/1000 -> #REF! | L21: =H21*1000/F21 -> #REF! | M21: =K21*1000/I21 -> #REF! | N21: 6.45
B22: 10 | C22: SECTION 6-6 | D22: 1 | E22: =$D22*'RW Footing'!#REF! -> #REF! | F22: =$D22*'RW Footing'!#REF! -> #REF! | G22: =$D22*'RW Footing'!#REF! -> #REF! | H22: =$D22*'RW Footing'!#REF!/1000 -> #REF! | I22: ='Retaining wall'!I46 -> 1.4976 | J22: ='Retaining wall'!J46 -> 15.296 | K22: =$D22*'Retaining wall'!#REF!/1000 -> #REF! | L22: =H22*1000/F22 -> #REF! | M22: =K22*1000/I22 -> #REF! | N22: 4.68
B23: Total | E23: =SUM(E8:E19) -> #REF! | F23: =SUM(F8:F19) -> #REF! | G23: =SUM(G8:G19) -> #REF! | H23: =SUM(H8:H19) -> #REF! | I23: =SUM(I8:I22) -> 343.898 | J23: =SUM(J8:J22) -> 2220.9141 | K23: =SUM(K8:K19) -> 0
B24: Kg/ Cu.m | C24: Kg/ Cu.m | H24: =H23*1000/F23 -> #REF! | K24: =K23*1000/I23 -> 0 | N24: =SUM(N8:N23) -> 263.01948
B27: S.No | C27: Description | D27: UOM | E27: Quantity | F27: Remarks
B28: 1 | C28: Retaining wall Footing
C29: PCC - M7.5 / M10 | D29: Cu.m | E29: =E23 -> #REF!
C30: Concrete - RMC M25 | D30: Cu.m | E30: =F23 -> #REF!
C31: Shuttering | D31: Sq.m | E31: =G23 -> #REF!
C32: Reinforcement | D32: MT | E32: =SUM(E33:E38) -> 0 | F32: Dia wise breakup as below
C33: TMT- 8mm | D33: MT | E33: ='RW Footing'!H11 -> 0
C34: TMT- 10mm | D34: MT | E34: ='RW Footing'!I11 -> 0
C35: TMT- 12mm | D35: MT | E35: ='RW Footing'!J11 -> 0
C36: TMT- 16mm | D36: MT | E36: ='RW Footing'!K11 -> 0
C37: TMT- 20mm | D37: MT | E37: ='RW Footing'!L11 -> 0
C38: TMT- 25mm | D38: MT | E38: ='RW Footing'!M11 -> 0
B39: 2 | C39: Retaining wall Stem | F39: Drain section will be extra, depth confirmation not available
C40: Concrete - RMC M25 | D40: Cu.m | E40: =I23 -> 343.898
C41: Shuttering | D41: Sq.m | E41: =J23 -> 2220.9141
C42: Reinforcement | D42: MT | E42: =SUM(E43:E48) -> 0 | F42: Dia wise breakup as below
C43: TMT- 8mm | D43: MT | E43: ='Retaining wall'!G16 -> 0
C44: TMT- 10mm | D44: MT | E44: ='Retaining wall'!H16 -> 0
...

Sheet RW Footing
A2: Project Name : | C2: Trust Office | H2: Cover-Top & Bottom | J2: =0.05 -> 0.05
A3: Drawings Referred : | C3: Retaining wall Footing details | H3: Cover-Sides | J3: =0.075 -> 0.075
H4: Bend Length | J4: =0.15 -> 0.15
H5: PCC Depth | J5: =0.1 -> 0.1
A7: ABSTRACT
A8: Sl. No. | B8: Description | C8: RMC Grade | D8: PCC Grade | E8: PCC (cum) | F8: Concrete (Cum) M30 | G8: Shuttering (Sqm) | H8: 8 mm | I8: 10 mm | J8: 12 mm | K8: 16 mm | L8: 20 mm | M8: 25 mm | N8: 32 mm | O8: Total | P8: Kg/Cum | Q8: Cover blocks | R8: Excavation Qty | S8: PCC Shuttering
A9: 1 | B9: Retaining wall Footing | C9: M25 | D9: M7.5 | E9: =S30 -> 70.879035 | F9: =Q30 -> 428.34192 | G9: =R30 -> 277.61689 | H9: =H30 -> 0 | I9: =I30 -> 0 | J9: =J30 -> 0 | K9: =K30 -> 0 | L9: =L30 -> 0 | M9: =M30 -> 0 | N9: =N30 -> 0 | O9: =SUM(H9:N9) -> 0 | P9: =(O9*1000)/F9 -> 0 | Q9: =ROUNDUP(G9*4,0) -> 1111 | R9: =T30 -> 2435.9668 | S9: =Z30 -> 186.83411
B11: TOTAL | E11: =SUM(E9:E10) -> 70.879035 | F11: =SUM(F9:F10) -> 428.34192 | G11: =SUM(G9:G10) -> 277.61689 | H11: =SUM(H9:H10) -> 0 | I11: =SUM(I9:I10) -> 0 | J11: =SUM(J9:J10) -> 0 | K11: =SUM(K9:K10) -> 0 | L11: =SUM(L9:L10) -> 0 | ... O11: =SUM(O9:O10) -> 0 | P11: =SUM(P9:P10)/2 -> 0
I12: 11.47 | J12: 4.5 | K12: 5.58 | L12: 5.22 | M12: 5.66
B13: DEVELOPMENT & ANCHORAGE LENGTHS - FE550
B14: Bar Diameter (mm) | C14: M20 | D14: M25 | E14: M30 | F14: M35 | G14: M40
B15: 8 | C15: =0.475 -> 0.475 | D15: =0.4 -> 0.4 | E15: 0.4 | F15: =0.325 -> 0.325 | G15: =0.3 -> 0.3
B16: 10 | C16: =0.575 -> 0.575 | D16: =0.5 -> 0.5 | E16: 0.5 | F16: =0.4 -> 0.4 | G16: =0.375 -> 0.375
B17: 12 | C17: =0.7 -> 0.7 | D17: =0.6 -> 0.6 | E17: 0.6 | F17: =0.5 -> 0.5 | G17: =0.45 -> 0.45
B18: 16 | C18: =0.925 -> 0.925 | D18: =0.8 -> 0.8 | E18: 0.8 | F18: =0.65 -> 0.65 | G18: =0.575 -> 0.575
B19: 20 | C19: =1.15 -> 1.15 | D19: =0.975 -> 0.975 | E19: 1 | F19: =0.8 -> 0.8 | G19: =0.725 -> 0.725
B20: 25 | C20: =1.425 -> 1.425 | D20: =1.225 -> 1.225 | E20: 1.25 | F20: =1 -> 1 | G20: =0.9 -> 0.9
B21: 28 | C21: =1.6 -> 1.6 | D21: =1.375 -> 1.375 | E21: =1.275 -> 1.275 | F21: =1.125 -> 1.125 | G21: =1.025 -> 1.025
B22: 32 | C22: =1.825 -> 1.825 | D22: =1.575 -> 1.575 | E22: 1.595 | F22: =1.3 -> 1.3 | G22: =1.15 -> 1.15
B24: GRADE OF CONCRETE | C24: M30 | D24: Depth of PCC | E24: 0.1
B25: Top & Bottom Cover | C25: 0.05 | D25: Depth of excavation | E25: 0.2 | G25: Dia: | H25: 8 | I25: 10 | J25: 12 | K25: 16 | L25: 20 | M25: 25 | N25: 32 | O25: Total Qty in Kg | P25: Total Kg/Cum | Q25: Concrete Qty | R25: Shuttering Qty | S25: PCC Qty | T25: Excavation | U25: Surface Trimming | V25: Footing Nos | W25: Backfilling Qty | X25: Anti Termite Treatment | Z25: PCC Shuttering | AA25: Cover Blocks
B26: Cover | C26: 0.05 | D26: Bend length | E26: 0.15 | F26: PCC extension | G26: Unit Weight (Kg/Rmt): | H26: =22/7/4/1000/1000*7850*H25*H25 -> 0.39474286 | I26: =22/7/4/1000/1000*7850*I25*I25 -> 0.61678571 | J26: =22/7/4/1000/1000*7850*J25*J25 -> 0.88817143 | K26: =22/7/4/1000/1000*7850*K25*K25 -> 1.5789714 | L26: =22/7/4/1000/1000*7850*L25*L25 -> 2.4671429 | M26: =22/7/4/1000/1000*7850*M25*M25 -> 3.8549107 | N26: =22/7/4/1000/1000*7850*N25*N25 -> 6.3158857
B27: Total footings: | F27: 0.075
AB28: Existing Level | AC28: FGL
C29: Nos | D29: Length/Area | E29: Breadth/ Perimeter | F29: Depth | G29: Concrete breadth | AA29: =SUM(AA31:AA31) -> 0
B30: RETAINING WALL FOOTING | H30: =SUM(H31:H31)*H26/1000 -> 0 | I30: =SUM(I31:I31)*I26/1000 -> 0 | J30: =SUM(J31:J31)*J26/1000 -> 0 | K30: =SUM(K31:K31)*K26/1000 -> 0 | L30: =SUM(L31:L31)*L26/1000 -> 0 | M30: =SUM(M31:M31)*M26/1000 -> 0 | N30: =SUM(N31:N31)*N26/1000 -> 0 | O30: =SUM(O31:O31)/1000 -> 0 | Q30: =SUM(Q31:Q52) -> 428.34192 | R30: =SUM(R31:R52) -> 277.61689 | S30: =SUM(S31:S52) -> 70.879035 | T30: =SUM(T31:T52) -> 2435.9668 | U30: =SUM(U31:U52) -> 708.79035 | V30: =SUM(V31:V52) -> 0 | W30: =SUM(W31:W52) -> 0 | X30: =SUM(X31:X52) -> 0 | ... Z30: =SUM(Z31:Z52) -> 186.83411
A31: 1 | B31: RF-01 | C31: 1 | D31: 70.31 | E31: 3 | F31: 0.5 | G31: =+E31 -> 3 | Q31: =C31*D31*F31*G31 -> 105.465 | R31: =((D31*F31+E31*F31)*2)-2.7245241 -> 70.585476 | S31: =((D31+$F$27*2)*(E31+$F$27*2))*$E$24*C31 -> 22.1949 | T31: =((D31+0.3*2)*(E31+0.3*2))*C31*AD31 -> 883.25496 | U31: =+S31/0.1 -> 221.949 | Z31: =(D31+E31)*2*$E$24*C31 -> 14.662 | AB31: =AVERAGE(102.552,101.078,98.5) -> 100.71 | AC31: =97.25 -> 97.25 | AD31: =AB31-AC31 -> 3.46
A32: =A31+1 -> 2 | B32: RF-02-PL (Incl Services) | C32: 1 | D32: 175.37429 | E32: 112.35303 | F32: 0.6 | G32: =+E32 -> 112.35303 | Q32: =C32*D32*F32 -> 105.22457 | R32: =(E32*F32)-(2.724+3.418+0.7) -> 60.569817 | S32: =112.974898*E24*C32 -> 11.29749 | T32: =((D32+0.3*2))*C32*AD32 -> 617.66976 | U32: =+S32/0.1 -> 112.9749 | Z32: =(D32+E32)*2*$E$24*C32 -> 57.545464 | AB32: =AVERAGE(102.552,101.078,98.5) -> 100.71 | AC32: 97.2 | AD32: =AB32-AC32 -> 3.51
A33: =A32+1 -> 3 | B33: RF-03 | C33: 1 | D33: 1.445 | E33: 0.7 | F33: 0.6 | G33: =+E33 -> 0.7 | Q33: =C33*D33*F33*G33 -> 0.6069 | R33: =(D33*F33)*2 -> 1.734 | S33: =((D33+$F$27*2)*(E33+$F$27*2))*$E$24*C33 -> 0.135575 | T33: =((D33+0.3*2)*(E33+0.3*2))*C33*AD33 -> 8.374275 | U33: =+S33/0.1 -> 1.35575 | Z33: =(D33+E33)*2*$E$24*C33 -> 0.429 | AB33: =AVERAGE(98.5) -> 98.5 | AC33: 95.35 | AD33: =AB33-AC33 -> 3.15
A34: =A33+1 -> 4 | B34: RF-04 | C34: 1 | D34: 1.7 | E34: 0.7 | F34: 0.6 | G34: =+E34 -> 0.7 | Q34: =C34*D34*F34*G34 -> 0.714 | R34: =(D34*F34)*2 -> 2.04 | S34: =((D34+$F$27*2)*(E34+$F$27*2))*$E$24*C34 -> 0.15725 | T34: =((D34+0.3*2)*(E34+0.3*2))*C34*AD34 -> 9.4185 | U34: =+S34/0.1 -> 1.5725 | Z34: =(D34+E34)*2*$E$24*C34 -> 0.48 | AB34: =AVERAGE(98.5) -> 98.5 | AC34: 95.35 | AD34: =AB34-AC34 -> 3.15
A35: =A34+1 -> 5 | B35: RF-05-PL | C35: 1 | D35: 4.0817571 | E35: 10.489278 | F35: 0.6 | G35: =+E35 -> 10.489278 | Q35: =C35*D35*F35 -> 2.4490543 | R35: =(E35*F35)-(0.7*2) -> 4.8935666 | S35: =10.9392646*E24*C35 -> 1.0939265 | T35: =((D35+0.3*2))*C35*AD35 -> 14.747535 | U35: =+S35/0.1 -> 10.939265 | Z35: =(D35+E35)*2*$E$24*C35 -> 2.9142069 | AB35: =AVERAGE(98.5) -> 98.5 | AC35: 95.35 | AD35: =AB35-AC35 -> 3.15
A36: =A35+1 -> 6 | B36: RF-06-PL | C36: 1 | D36: 3.4593804 | E36: 9.3989163 | F36: 0.6 | G36: =+E36 -> 9.3989163 | Q36: =C36*D36*F36 -> 2.0756282 | R36: =(E36*F36)-(0.7*2) -> 4.2393498 | S36: =9.9989165*E24*C36 -> 0.99989165 | T36: =((D36+0.3*2))*C36*AD36 -> 12.787048 | U36: =+S36/0.1 -> 9.9989165 | Z36: =(D36+E36)*2*$E$24*C36 -> 2.5716593 | AB36: =AVERAGE(98.5) -> 98.5 | AC36: 95.35 | AD36: =AB36-AC36 -> 3.15
A37: =A36+1 -> 7 | B37: RF-07-PL | C37: 1 | D37: 126.34159 | E37: 82.21753 | F37: 0.6 | G37: =+E37 -> 82.21753 | Q37: =C37*D37*F37 -> 75.804954 | R37: =(E37*F37)-(0.7+2.6) -> 46.030518 | S37: =82.8175296*E24*C37 -> 8.281753 | T37: =((D37+0.3*2))*C37*AD37 -> 483.64746 | U37: =+S37/0.1 -> 82.81753 | Z37: =(D37+E37)*2*$E$24*C37 -> 41.711824 | AB37: =AVERAGE(102.552,101.078,98.5) -> 100.71 | AC37: 96.9 | AD37: =AB37-AC37 -> 3.81
A38: =A37+1 -> 8 | B38: RF-08-PL | C38: 1 | D38: 38.720409 | E38: 37.90283 | F38: 0.45 | G38: =+E38 -> 37.90283 | Q38: =C38*D38*F38 -> 17.424184 | R38: =(E38*F38)-(2.6+1.5) -> 12.956273 | S38: =38.3517344*E24*C38 -> 3.8351734 | T38: =((D38+0.3*2))*C38*AD38 -> 149.81076 | U38: =+S38/0.1 -> 38.351734 | Z38: =(D38+E38)*2*$E$24*C38 -> 15.324648 | AB38: =AVERAGE(102.552,101.078,98.5) -> 100.71 | AC38: 96.9 | AD38: =AB38-AC38 -> 3.81
A39: =A38+1 -> 9 | B39: RF-09 | C39: 1 | D39: 6.717 | E39: 1.497 | F39: 0.35 | G39: =+E39 -> 1.497 | Q39: =C39*D39*F39*G39 -> 3.5193721 | R39: =(D39*F39)*2+E39*F39 -> 5.22585 | S39: =((D39+$F$27*2)*(E39+$F$27*2))*$E$24*C39 -> 1.1309949 | T39: =((D39+0.3*2)*(E39+0.3*2))*C39*AD39 -> 3.2221873 | U39: =+S39/0.1 -> 11.309949 | Z39: =(D39+E39)*2*$E$24*C39 -> 1.6428 | AB39: =AVERAGE(102.552,101.078,98.5) -> 100.71 | AC39: 100.5 | AD39: =AB39-AC39 -> 0.21
A40: =A39+1 -> 10 | B40: RF-10-PL | C40: 1 | D40: 21.919909 | E40: 20.598489 | F40: 0.5 | G40: =+E40 -> 20.598489 | Q40: =C40*D40*F40 -> 10.959955 | R40: =(E40*F40)-(2.405+3.02) -> 4.8742447 | S40: =21.1961113*$E$24*C40 -> 2.1196111 | T40: =((D40+0.3*2))*C40*AD40 -> 4.729181 | U40: =+S40/0.1 -> 21.196111 | Z40: =(D40+E40)*2*$E$24*C40 -> 8.5036798 | AB40: =AVERAGE(102.552,101.078,98.5) -> 100.71 | AC40: 100.5 | AD40: =AB40-AC40 -> 0.21
A41: =A40+1 -> 11 | B41: RF-11 | C41: 1 | D41: 2.422 | E41: 4.617 | F41: 0.45 | G41: =+E41 -> 4.617 | Q41: =C41*D41*F41*G41 -> 5.0320683 | R41: =(D41*F41)*2 -> 2.1798 | S41: =((D41+$F$27*2)*(E41+$F$27*2))*$E$24*C41 -> 1.2260724 | T41: =((D41+0.3*2)*(E41+0.3*2))*C41*AD41 -> 16.002261 | U41: =+S41/0.1 -> 12.260724 | Z41: =(D41+E41)*2*$E$24*C41 -> 1.4078 | AB41: =AVERAGE(102.552,101.078) -> 101.815 | AC41: =102-1.2 -> 100.8 | AD41: =AB41-AC41 -> 1.015
A42: =A41+1 -> 12 | B42: RF-12-PL | C42: 1 | D42: 47.952117 | E42: 36.147349 | F42: 0.6 | G42: =+E42 -> 36.147349 | Q42: =C42*D42*F42 -> 28.77127 | R42: =(E42*F42)-(2.42) -> 19.26841 | S42: =36.7491957*$E$24*C42 -> 3.6749196 | T42: =((D42+0.3*2))*C42*AD42 -> 49.280399 | U42: =+S42/0.1 -> 36.749196 | Z42: =(D42+E42)*2*$E$24*C42 -> 16.819893 | AB42: =AVERAGE(102.552,101.078) -> 101.815 | AC42: =102-1.2 -> 100.8 | AD42: =AB42-AC42 -> 1.015
A43: =A42+1 -> 13 | B43: RF-13 | C43: 1 | D43: 4.173 | E43: 2.8 | F43: 0.5 | G43: =+E43 -> 2.8 | Q43: =C43*D43*F43*G43 -> 5.8422 | R43: =(D43*F43)*2 -> 4.173 | S43: =((D43+$F$27*2)*(E43+$F$27*2))*$E$24*C43 -> 1.275285 | T43: =((D43+0.3*2)*(E43+0.3*2))*C43*AD43 -> 16.471623 | U43: =+S43/0.1 -> 12.75285 | Z43: =(D43+E43)*2*$E$24*C43 -> 1.3946 | AB43: =AVERAGE(102.552,101.078) -> 101.815 | AC43: =102-1.2 -> 100.8 | AD43: =AB43-AC43 -> 1.015
A44: =A43+1 -> 14 | B44: RF-14 | C44: 1 | D44: 3.95 | E44: 4.2 | F44: 0.5 | G44: =+E44 -> 4.2 | Q44: =C44*D44*F44*G44 -> 8.295 | R44: =(D44*F44)*2 -> 3.95 | S44: =((D44+$F$27*2)*(E44+$F$27*2))*$E$24*C44 -> 1.7835 | T44: =((D44+0.3*2)*(E44+0.3*2))*C44*AD44 -> 22.1676 | U44: =+S44/0.1 -> 17.835 | Z44: =(D44+E44)*2*$E$24*C44 -> 1.63 | AB44: =AVERAGE(102.552,101.078) -> 101.815 | AC44: =102-1.2 -> 100.8 | AD44: =AB44-AC44 -> 1.015
...

Sheet Retaining wall
A2: Project Name : | C2: Trust Office | H2: Footing Depth | J2: 0.6
A3: Drawings Referred : | C3: Retaining wall details | H3: Cover | J3: =40/1000 -> 0.04
H4: Bend Length | J4: 0.3
H5: PCC Depth | J5: =0.1 -> 0.1
A7: ABSTRACT
A8: Sl. No. | B8: Description | C8: RMC Grade | D8: Grade of steel | E8: Concrete (Cum) M30 | F8: Shuttering (Sqm) | G8: 8 mm | H8: 10 mm | I8: 12 mm | J8: 16 mm | K8: 20 mm | L8: 25 mm | M8: 32 mm | N8: Total | O8: Kg/Cum | P8: Guage Piece | Q8: Tie rods | R8: Water Proofing | S8: Cover Blocks 45 mm as per structure | T8: Water Stopper
A9: 1 | B9: Retaining Wall | C9: M30 | D9: FE550 | E9: =I31 -> 343.898 | F9: =J31 -> 2199.2841 | G9: =K31 -> 0 | H9: =L31 -> 0 | I9: =M31 -> 0 | J9: =N31 -> 0 | K9: =O31 -> 0 | L9: =P31 -> 0 | M9: =Q31 -> 0 | N9: =SUM(G9:M9) -> 0 | O9: =(N9*1000)/E9 -> 0 | P9: =T31 -> 3066 | Q9: =U31 -> 3066 | R9: =V31 -> 1055.199 | S9: =W31 -> 8441.5923
A10: 2 | B10: Counter Fort | C10: M30 | D10: FE550 | E10: =I67 -> 37.314 | F10: =J67 -> 269.67 | R10: =V67 -> 269.67
B16: TOTAL | E16: =SUM(E9:E15) -> 381.212 | F16: =SUM(F9:F15) -> 2468.9541 | G16: =SUM(G9:G15) -> 0 | H16: =SUM(H9:H15) -> 0 | I16: =SUM(I9:I15) -> 0 | J16: =SUM(J9:J15) -> 0 | K16: =SUM(K9:K15) -> 0 | L16: =SUM(L9:L15) -> 0 | ... N16: =SUM(N9:N15) -> 0 | O16: =AVERAGE(O9:O10) -> 0 | P16: =SUM(P9:P15) -> 3066 | Q16: =SUM(Q9:Q15) -> 3066 | R16: =SUM(R9:R15) -> 1324.869 | S16: =SUM(S9:S15) -> 8441.5923
E17: =E16/Abstract!N24/0.45 -> 3.2208175 | R17: =+R16*0.6 -> 794.92143
B19: Development Length & Anchorage | I19: GF lvl | J19: 11.4
B20: Bar Diameter (mm) | C20: M20 | D20: M25 | E20: M30 | F20: M35 | G20: M40 | I20: Footing Top lvl | J20: =6.2+0.45 -> 6.65
B21: 8 | C21: =0.475 -> 0.475 | D21: =0.4 -> 0.4 | E21: 0.4 | F21: =0.325 -> 0.325 | G21: =0.3 -> 0.3 | I21: Height of Retaining wall | J21: =J19-J20 -> 4.75
B22: 10 | C22: =0.575 -> 0.575 | D22: =0.5 -> 0.5 | E22: 0.5 | F22: =0.4 -> 0.4 | G22: =0.375 -> 0.375 | I22: 200mm Wall Height | J22: 0.6
B23: 12 | C23: =0.7 -> 0.7 | D23: =0.6 -> 0.6 | E23: 0.6 | F23: =0.5 -> 0.5 | G23: =0.45 -> 0.45 | I23: Haunching bar | J23: =0.3+0.3+0.6 -> 1.2
B24: 16 | C24: =0.925 -> 0.925 | D24: =0.8 -> 0.8 | E24: 0.8 | F24: =0.65 -> 0.65 | G24: =0.575 -> 0.575
B25: 20 | C25: =1.15 -> 1.15 | D25: =0.975 -> 0.975 | E25: 1 | F25: =0.8 -> 0.8 | G25: =0.725 -> 0.725
B26: 25 | C26: =1.425 -> 1.425 | D26: =1.225 -> 1.225 | E26: 1.25 | F26: =1 -> 1 | G26: =0.9 -> 0.9
B27: 32 | C27: =1.825 -> 1.825 | D27: =1.575 -> 1.575 | E27: 1.595 | F27: =1.3 -> 1.3 | G27: =1.15 -> 1.15
A29: S.no | B29: Description | C29: Nos | D29: Dia | E29: Spacing | F29: No of Rods | G29: Rod Length | H29: Total Length | I29: Concrete | J29: Shuttering | K29: 8 | L29: 10 | M29: 12 | N29: 16 | O29: 20 | P29: 25 | Q29: 32 | R29: Steel in KG | S29: Kg/Cum | T29: Gauge Piece | U29: Tie Rod | V29: Retaining wall water proofing | W29: Cover Blocks | X29: Cerabitoplast for WP | Y29: =V31*0.6 -> 633.11943
K30: =22/7/4/1000/1000*7850*K29*K29 -> 0.39474286 | L30: =22/7/4/1000/1000*7850*L29*L29 -> 0.61678571 | M30: =22/7/4/1000/1000*7850*M29*M29 -> 0.88817143 | N30: =22/7/4/1000/1000*7850*N29*N29 -> 1.5789714 | O30: =22/7/4/1000/1000*7850*O29*O29 -> 2.4671429 | P30: =22/7/4/1000/1000*7850*P29*P29 -> 3.8549107 | Q30: =22/7/4/1000/1000*7850*Q29*Q29 -> 6.3158857
D31: Length | E31: Breadth | F31: Depth | I31: =SUM(I33:I50) -> 343.898 | J31: =SUM(J33:J50) -> 2199.2841 | K31: =SUM(K33:K43)*K30/1000 -> 0 | L31: =SUM(L33:L43)*L30/1000 -> 0 | M31: =SUM(M33:M43)*M30/1000 -> 0 | N31: =SUM(N33:N43)*N30/1000 -> 0 | O31: =SUM(O33:O43)*O30/1000 -> 0 | P31: =SUM(P33:P43)*P30/1000 -> 0 | Q31: =SUM(Q33:Q43)*Q30/1000 -> 0 | R31: =SUM(R33:R43) -> 0 | T31: =SUM(T33:T43) -> 3066 | U31: =SUM(U33:U43) -> 3066 | V31: =SUM(V33:V43) -> 1055.199 | W31: =SUM(W33:W43) -> 8441.5923
X32: Nos
A33: 1 | B33: =Abstract!C8 -> SECTION-1-1 | C33: 1 | D33: =Abstract!N8 -> 70.306484 | E33: 0.35 | F33: 3.6 | I33: =C33*D33*E33*F33 -> 88.58617 | J33: =C33*(D33*F33*2+E33*F33) -> 507.46669 | T33: =ROUNDUP(D33/0.6,0)*ROUNDUP(F33/0.6,0) -> 708 | U33: =ROUNDUP(D33/0.6,0)*ROUNDUP(F33/0.6,0) -> 708 | V33: =+D33*F33 -> 253.10334 | W33: =(D33*F33)*4*2 -> 2024.8267 | X33: =+T33+T37+#REF!+#REF!+#REF! -> #REF! | Z33: =C33*D33*E33 -> 24.607269
A34: =A33+1 -> 2 | B34: =Abstract!C9 -> SECTION 1A-1A | C34: 1 | D34: =Abstract!N9 -> 5.561 | E34: 0.35 | F34: 2.3 | I34: =C34*D34*E34*F34 -> 4.476605 | J34: =C34*D34*F34*2 -> 25.5806 | T34: =ROUNDUP(D34/0.6,0)*ROUNDUP(F34/0.6,0) -> 40 | U34: =ROUNDUP(D34/0.6,0)*ROUNDUP(F34/0.6,0) -> 40 | V34: =+D34*F34 -> 12.7903 | W34: =(D34*F34)*4*2 -> 102.3224 | X34: =+T34+#REF!+#REF!+#REF!+#REF! -> #REF! | Y34: 300 mm
A35: =A34+1 -> 3 | B35: =Abstract!C10 -> SECTION 2A-2A | C35: 1 | D35: =Abstract!N10 -> 7.298 | E35: 0.3 | F35: 5.7 | I35: =C35*D35*E35*F35 -> 12.47958 | J35: =C35*D35*F35*2 -> 83.1972 | T35: =ROUNDUP(D35/0.6,0)*ROUNDUP(F35/0.6,0) -> 130 | U35: =ROUNDUP(D35/0.6,0)*ROUNDUP(F35/0.6,0) -> 130 | V35: =+D35*F35 -> 41.5986 | W35: =(D35*F35)*4*2 -> 332.7888 | X35: =+T35+#REF!+#REF!+#REF!+#REF! -> #REF! | Y35: 300 mm
A36: =A35+1 -> 4 | B36: =Abstract!C11 -> SECTION 2B-2B | C36: 1 | D36: =Abstract!N11 -> 6.16 | E36: 0.3 | F36: 4.7 | I36: =C36*D36*E36*F36 -> 8.6856 | J36: =C36*D36*F36*2 -> 57.904 | T36: =ROUNDUP(D36/0.6,0)*ROUNDUP(F36/0.6,0) -> 88 | U36: =ROUNDUP(D36/0.6,0)*ROUNDUP(F36/0.6,0) -> 88 | V36: =+D36*F36 -> 28.952 | W36: =(D36*F36)*4*2 -> 231.616 | X36: =+T36+#REF!+#REF!+#REF!+#REF! -> #REF! | Y36: 300 mm
A37: =A36+1 -> 5 | B37: =Abstract!C12 -> SECTION 7-7 | C37: 1 | D37: =Abstract!N12 -> 7.89 | E37: 0.3 | F37: 4.2 | I37: =C37*D37*E37*F37 -> 9.9414 | J37: =C37*D37*F37*2 -> 66.276 | T37: =ROUNDUP(D37/0.6,0)*ROUNDUP(F37/0.6,0) -> 98 | U37: =ROUNDUP(D37/0.6,0)*ROUNDUP(F37/0.6,0) -> 98 | V37: =+D37*F37 -> 33.138 | W37: =(D37*F37)*4*2 -> 265.104
A38: =A37+1 -> 6 | B38: =Abstract!C13 -> SECTION 8-8 | C38: 1 | D38: =Abstract!N13 -> 7.54 | E38: 0.3 | F38: 3.05 | I38: =C38*D38*E38*F38 -> 6.8991 | J38: =C38*D38*F38*2 -> 45.994 | T38: =ROUNDUP(D38/0.6,0)*ROUNDUP(F38/0.6,0) -> 78 | U38: =ROUNDUP(D38/0.6,0)*ROUNDUP(F38/0.6,0) -> 78 | V38: =+D38*F38 -> 22.997 | W38: =(D38*F38)*4*2 -> 183.976
A39: =A38+1 -> 7 | B39: =Abstract!C14 -> SECTION 9-9 | C39: 1 | D39: =Abstract!N14 -> 13.36 | E39: 0.3 | F39: 4.4 | I39: =C39*D39*E39*F39 -> 17.6352 | J39: =C39*D39*F39*2 -> 117.568 | T39: =ROUNDUP(D39/0.6,0)*ROUNDUP(F39/0.6,0) -> 184 | U39: =ROUNDUP(D39/0.6,0)*ROUNDUP(F39/0.6,0) -> 184 | V39: =+D39*F39 -> 58.784 | W39: =(D39*F39)*4*2 -> 470.272
A40: =A39+1 -> 8 | B40: =Abstract!C15 -> SECTION 10-10 | C40: 1 | D40: =Abstract!N15 -> 2.9 | E40: 0.3 | F40: 4.35 | I40: =C40*D40*E40*F40 -> 3.7845 | J40: =C40*D40*F40*2 -> 25.23 | T40: =ROUNDUP(D40/0.6,0)*ROUNDUP(F40/0.6,0) -> 40 | U40: =ROUNDUP(D40/0.6,0)*ROUNDUP(F40/0.6,0) -> 40 | V40: =+D40*F40 -> 12.615 | W40: =(D40*F40)*4*2 -> 100.92
A41: =A40+1 -> 9 | B41: =Abstract!C16 -> SECTION 11-11 | C41: 1 | D41: =Abstract!N16 -> 60.974 | E41: 0.3 | F41: 4.2 | I41: =C41*D41*E41*F41 -> 76.82724 | J41: =C41*D41*F41*2 -> 512.1816 | T41: =ROUNDUP(D41/0.6,0)*ROUNDUP(F41/0.6,0) -> 714 | U41: =ROUNDUP(D41/0.6,0)*ROUNDUP(F41/0.6,0) -> 714 | V41: =+D41*F41 -> 256.0908 | W41: =(D41*F41)*4*2 -> 2048.7264 | X41: =+T41+#REF!+#REF!+#REF!+#REF! -> #REF! | Y41: 300 mm
A42: =A41+1 -> 10 | B42: =Abstract!C18 -> SECTION 2-2 | C42: 1 | D42: =Abstract!N18 -> 50.9 | E42: 0.3 | F42: 5.7 | I42: =C42*D42*E42*F42 -> 87.039 | J42: =C42*D42*F42*2 -> 580.26 | T42: =ROUNDUP(D42/0.6,0)*ROUNDUP(F42/0.6,0) -> 850 | U42: =ROUNDUP(D42/0.6,0)*ROUNDUP(F42/0.6,0) -> 850 | V42: =+D42*F42 -> 290.13 | W42: =(D42*F42)*4*2 -> 2321.04 | X42: =+T42+T65+#REF!+#REF!+#REF! -> #REF! | Y42: 300 mm
A43: =A42+1 -> 11 | B43: =Abstract!C19 -> SECTION 3-3 | C43: 1 | D43: =Abstract!N19 -> 10 | E43: 0.3 | F43: 4.5 | I43: =C43*D43*E43*F43 -> 13.5 | J43: =C43*D43*F43*2 -> 90 | T43: =ROUNDUP(D43/0.6,0)*ROUNDUP(F43/0.6,0) -> 136 | U43: =ROUNDUP(D43/0.6,0)*ROUNDUP(F43/0.6,0) -> 136 | V43: =+D43*F43 -> 45 | W43: =(D43*F43)*4*2 -> 360
A44: =A43+1 -> 12 | B44: =Abstract!C20 -> SECTION 4-4 | C44: 1 | D44: =Abstract!N20 -> 9 | E44: 0.3 | F44: 3.5 | I44: =C44*D44*E44*F44 -> 9.45 | J44: =C44*D44*F44*2 -> 63 | T44: =ROUNDUP(D44/0.6,0)*ROUNDUP(F44/0.6,0) -> 90 | U44: =ROUNDUP(D44/0.6,0)*ROUNDUP(F44/0.6,0) -> 90 | V44: =+D44*F44 -> 31.5 | W44: =(D44*F44)*4*2 -> 252
A45: =A44+1 -> 13 | B45: =Abstract!C21 -> SECTION 5-5 | C45: 1 | D45: =Abstract!N21 -> 6.45 | E45: 0.2 | F45: 2.4 | I45: =C45*D45*E45*F45 -> 3.096 | J45: =C45*D45*F45*2 -> 30.96 | T45: =ROUNDUP(D45/0.6,0)*ROUNDUP(F45/0.6,0) -> 44 | U45: =ROUNDUP(D45/0.6,0)*ROUNDUP(F45/0.6,0) -> 44 | V45: =+D45*F45 -> 15.48 | W45: =(D45*F45)*4*2 -> 123.84
A46: =A45+1 -> 14 | B46: =Abstract!C22 -> SECTION 6-6 | C46: 1 | D46: =Abstract!N22 -> 4.68 | E46: 0.2 | F46: 1.6 | I46: =C46*D46*E46*F46 -> 1.4976 | J46: =C46*(D46*F46*2+E46*F46) -> 15.296 | T46: =ROUNDUP(D46/0.6,0)*ROUNDUP(F46/0.6,0) -> 24 | U46: =ROUNDUP(D46/0.6,0)*ROUNDUP(F46/0.6,0) -> 24 | V46: =+D46*F46 -> 7.488 | W46: =(D46*F46)*4*2 -> 59.904
A47: =A46+1 -> 15 | B47: Deduction For Counterfort Shuttering | I47: =C47*D47*E47*F47 -> 0 | J47: =C47*(D47*F47*2+E47*F47) -> 0 | T47: =ROUNDUP(D47/0.6,0)*ROUNDUP(F47/0.6,0) -> 0 | U47: =ROUNDUP(D47/0.6,0)*ROUNDUP(F47/0.6,0) -> 0 | V47: =+D47*F47 -> 0 | W47: =(D47*F47)*4*2 -> 0
B48: SECTION 2A-2A | C48: -2 | D48: =Abstract!N10 -> 7.298 | E48: 0.3 | F48: 5.7 | J48: =C48*(E48*F48) -> -3.42 | S48: =SUM(R49:R56) -> 0
B49: SECTION 2B-2B | C49: -2 | D49: =Abstract!N11 -> 6.16 | E49: 0.3 | F49: 4.7 | J49: =C49*(E49*F49) -> -2.82 | S49: =SUM(R50:R57) -> 0
...

Sheet Footing
A2: Project Name : | C2: Trust Office | H2: Cover-Top & Bottom | J2: =0.05 -> 0.05
A3: Drawings Referred : | C3: Footing details | H3: Cover-Sides | J3: =0.075 -> 0.075
H4: Bend Length | J4: =0.15 -> 0.15
H5: PCC Depth | J5: =0.1 -> 0.1
A7: ABSTRACT
A8: Sl. No. | B8: Description | C8: RMC Grade | D8: PCC Grade | E8: PCC (cum) | F8: Concrete (Cum) M30 | G8: Shuttering (Sqm) | H8: 8 mm | I8: 10 mm | J8: 12 mm | K8: 16 mm | L8: 20 mm | M8: 25 mm | N8: 32 mm | O8: Total | P8: Kg/Cum | Q8: Cover blocks | R8: Excavation Qty | S8: PCC Shuttering
A9: 1 | B9: Footing | C9: M25 | D9: M7.5 | E9: =S30 -> 7.8629033 | F9: =Q30 -> 311.58958 | G9: =R30 -> 292.95216 | H9: =H30 -> 0 | I9: =I30 -> 0 | J9: =J30 -> 0 | K9: =K30 -> 0 | L9: =L30 -> 0 | M9: =M30 -> 0 | N9: =N30 -> 0 | O9: =SUM(H9:N9) -> 0 | P9: =(O9*1000)/F9 -> 0 | Q9: =ROUNDUP(G9*4,0) -> 1172 | R9: =T30 -> 1211.8379 | S9: =Z30 -> 51.989697
B11: TOTAL | E11: =SUM(E9:E10) -> 7.8629033 | F11: =SUM(F9:F10) -> 311.58958 | G11: =SUM(G9:G10) -> 292.95216 | H11: =SUM(H9:H10) -> 0 | I11: =SUM(I9:I10) -> 0 | J11: =SUM(J9:J10) -> 0 | K11: =SUM(K9:K10) -> 0 | L11: =SUM(L9:L10) -> 0 | ... O11: =SUM(O9:O10) -> 0 | P11: =SUM(P9:P10)/2 -> 0
I12: 11.47 | J12: 4.5 | K12: 5.58 | L12: 5.22 | M12: 5.66
B13: DEVELOPMENT & ANCHORAGE LENGTHS - FE550
B14: Bar Diameter (mm) | C14: M20 | D14: M25 | E14: M30 | F14: M35 | G14: M40
B15: 8 | C15: =0.475 -> 0.475 | D15: =0.4 -> 0.4 | E15: 0.4 | F15: =0.325 -> 0.325 | G15: =0.3 -> 0.3
B16: 10 | C16: =0.575 -> 0.575 | D16: =0.5 -> 0.5 | E16: 0.5 | F16: =0.4 -> 0.4 | G16: =0.375 -> 0.375
B17: 12 | C17: =0.7 -> 0.7 | D17: =0.6 -> 0.6 | E17: 0.6 | F17: =0.5 -> 0.5 | G17: =0.45 -> 0.45 | R17: Depth of excavation
B18: 16 | C18: =0.925 -> 0.925 | D18: =0.8 -> 0.8 | E18: 0.8 | F18: =0.65 -> 0.65 | G18: =0.575 -> 0.575
B19: 20 | C19: =1.15 -> 1.15 | D19: =0.975 -> 0.975 | E19: 1 | F19: =0.8 -> 0.8 | G19: =0.725 -> 0.725
B20: 25 | C20: =1.425 -> 1.425 | D20: =1.225 -> 1.225 | E20: 1.25 | F20: =1 -> 1 | G20: =0.9 -> 0.9
B21: 28 | C21: =1.6 -> 1.6 | D21: =1.375 -> 1.375 | E21: =1.275 -> 1.275 | F21: =1.125 -> 1.125 | G21: =1.025 -> 1.025
B22: 32 | C22: =1.825 -> 1.825 | D22: =1.575 -> 1.575 | E22: 1.595 | F22: =1.3 -> 1.3 | G22: =1.15 -> 1.15
B24: GRADE OF CONCRETE | C24: M30 | D24: Depth of PCC | E24: 0.1
B25: Top & Bottom Cover | C25: 0.05 | D25: Depth of excavation | E25: 0.2 | G25: Dia: | H25: 8 | I25: 10 | J25: 12 | K25: 16 | L25: 20 | M25: 25 | N25: 32 | O25: Total Qty in Kg | P25: Total Kg/Cum | Q25: Concrete Qty | R25: Shuttering Qty | S25: PCC Qty | T25: Excavation | U25: Surface Trimming | V25: Footing Nos | W25: Backfilling Qty | X25: Anti Termite Treatment | Z25: PCC Shuttering | AA25: Cover Blocks | AB25: Existing level | AC25: FL | AD25: Difference
B26: Cover | C26: 0.05 | D26: Bend length | E26: 0.15 | F26: PCC extension | G26: Unit Weight (Kg/Rmt): | H26: =22/7/4/1000/1000*7850*H25*H25 -> 0.39474286 | I26: =22/7/4/1000/1000*7850*I25*I25 -> 0.61678571 | J26: =22/7/4/1000/1000*7850*J25*J25 -> 0.88817143 | K26: =22/7/4/1000/1000*7850*K25*K25 -> 1.5789714 | L26: =22/7/4/1000/1000*7850*L25*L25 -> 2.4671429 | M26: =22/7/4/1000/1000*7850*M25*M25 -> 3.8549107 | N26: =22/7/4/1000/1000*7850*N25*N25 -> 6.3158857
B27: Total footings: | F27: 0.075
C29: Nos | D29: Length/Area | E29: Breadth/ Perimeter | F29: Depth | G29: Concrete breadth | AA29: =SUM(AA31:AA31) -> 0
B30: RETAINING WALL FOOTING | H30: =SUM(H31:H31)*H26/1000 -> 0 | I30: =SUM(I31:I31)*I26/1000 -> 0 | J30: =SUM(J31:J31)*J26/1000 -> 0 | K30: =SUM(K31:K31)*K26/1000 -> 0 | L30: =SUM(L31:L31)*L26/1000 -> 0 | M30: =SUM(M31:M31)*M26/1000 -> 0 | N30: =SUM(N31:N31)*N26/1000 -> 0 | O30: =SUM(O31:O31)/1000 -> 0 | Q30: =SUM(Q31:Q41) -> 311.58958 | R30: =SUM(R31:R41) -> 292.95216 | S30: =SUM(S31:S41) -> 7.8629033 | T30: =SUM(T31:T41) -> 1211.8379 | U30: =SUM(U31:U41) -> 78.629033 | V30: =SUM(V31:V31) -> 0 | W30: =SUM(W31:W31) -> 0 | X30: =SUM(X31:X31) -> 0 | Y30: =SUM(Y31:Y31) -> 0 | Z30: =SUM(Z31:Z41) -> 51.989697
A31: 1 | B31: F-01 | C31: 5 | D31: 4.6 | E31: 3.6 | F31: 1.1 | G31: =+E31 -> 3.6 | Q31: =C31*D31*F31*G31 -> 91.08 | R31: =((D31*F31+E31*F31)*2)*C31 -> 90.2 | S31: =((D31*$F$27*2)*(E31+$F$27*2))*$E$24*C31 -> 1.29375 | T31: =((D31+0.3*2)*(E31+0.3*2))*C31*AD31 -> 224.7882 | U31: =+S31/0.1 -> 12.9375 | Z31: =(D31+E31)*2*$E$24*C31 -> 8.2 | AB31: =AVERAGE(102.252,102.665) -> 102.4585 | AC31: =AVERAGE(100.4) -> 100.4 | AD31: =AB31-AC31 -> 2.0585
A32: =A31+1 -> 2 | B32: F-02 | C32: 5 | D32: 3.5 | E32: 2.6 | F32: 0.85 | G32: =+E32 -> 2.6 | Q32: =C32*D32*F32*G32 -> 38.675 | R32: =((D32*F32+E32*F32)*2)*C32 -> 51.85 | S32: =((D32*$F$27*2)*(E32+$F$27*2))*$E$24*C32 -> 0.721875 | T32: =((D32+0.3*2)*(E32+0.3*2))*C32*AD32 -> 162.5568 | U32: =+S32/0.1 -> 7.21875 | Z32: =(D32+E32)*2*$E$24*C32 -> 6.1 | AB32: 101.078 | AC32: =98.6 -> 98.6 | AD32: =AB32-AC32 -> 2.478
A33: =A32+1 -> 3 | B33: F-02A | C33: 3 | D33: 3.7 | E33: 2.6 | F33: 0.85 | G33: =+E33 -> 2.6 | Q33: =C33*D33*F33*G33 -> 24.531 | R33: =((D33*F33*2+E33*F33)+E33*0.25)*C33 -> 27.45 | S33: =((D33*$F$27*2)*(E33+$F$27*2))*$E$24*C33 -> 0.457875 | T33: =((D33+0.3*2)*(E33+0.3*2))*C33*AD33 -> 256.28688 | U33: =+S33/0.1 -> 4.57875 | Z33: =(D33+E33)*2*$E$24*C33 -> 3.78 | AB33: =AVERAGE(102.252,102.665) -> 102.4585 | AC33: =96.25 -> 96.25 | AD33: =AB33-AC33 -> 6.2085
A34: =A33+1 -> 4 | B34: F-03 | C34: 3 | D34: 1.45 | E34: 1.3 | F34: 0.45 | G34: =+E34 -> 1.3 | Q34: =C34*D34*F34*G34 -> 2.54475 | R34: =((D34*F34+E34*F34)*2)*C34 -> 7.425 | S34: =((D34*$F$27*2)*(E34+$F$27*2))*$E$24*C34 -> 0.0946125 | T34: =((D34+0.3*2)*(E34+0.3*2))*C34*AD34 -> 36.80775 | U34: =+S34/0.1 -> 0.946125 | Z34: =(D34+E34)*2*$E$24*C34 -> 1.65 | AB34: 98.5 | AC34: 95.35 | AD34: =AB34-AC34 -> 3.15
A35: =A34+1 -> 5 | B35: F-03A | C35: 1 | D35: 1.65 | E35: 1.4 | F35: 0.45 | G35: =+E35 -> 1.4 | Q35: =C35*D35*F35*G35 -> 1.0395 | R35: =((D35*F35+E35*F35)*2)*C35 -> 2.745 | S35: =((D35*$F$27*2)*(E35+$F$27*2))*$E$24*C35 -> 0.0383625 | T35: =((D35+0.3*2)*(E35+0.3*2))*C35*AD35 -> 14.175 | U35: =+S35/0.1 -> 0.383625 | Z35: =(D35+E35)*2*$E$24*C35 -> 0.61 | AB35: 98.5 | AC35: 95.35 | AD35: =AB35-AC35 -> 3.15
A36: =A35+1 -> 6 | B36: F-04 | C36: 1 | D36: 3.5 | E36: 2.5 | F36: 0.7 | G36: =+E36 -> 2.5 | Q36: =C36*D36*F36*G36 -> 6.125 | R36: =((D36*F36+E36*F36)*2)*C36-(2.8+2.875)*F36 -> 4.4275 | S36: =((D36*$F$27*2)*(E36+$F$27*2))*$E$24*C36 -> 0.139125 | T36: =((D36+0.3*2)*(E36+0.3*2))*C36*AD36 -> 8.61738 | U36: =+S36/0.1 -> 1.39125 | Z36: =(D36+E36)*2*$E$24*C36 -> 1.2 | AB36: 101.078 | AC36: 100.4 | AD36: =AB36-AC36 -> 0.678
A37: =A36+1 -> 7 | B37: F-05 | C37: 1 | D37: 2.7 | E37: 2 | F37: 0.7 | G37: =+E37 -> 2 | Q37: =C37*D37*F37*G37 -> 3.78 | R37: =((D37*F37+E37*F37)*2)*C37 -> 6.58 | S37: =((D37*$F$27*2)*(E37+$F$27*2))*$E$24*C37 -> 0.087075 | T37: =((D37+0.3*2)*(E37+0.3*2))*C37*AD37 -> 5.81724 | U37: =+S37/0.1 -> 0.87075 | Z37: =(D37+E37)*2*$E$24*C37 -> 0.94 | AB37: 101.078 | AC37: 100.4 | AD37: =AB37-AC37 -> 0.678
A38: =A37+1 -> 8 | B38: F-06 | C38: 6 | D38: 3.9 | E38: 3 | F38: 0.9 | G38: =+E38 -> 3 | Q38: =C38*D38*F38*G38 -> 63.18 | R38: =((D38*F38+E38*F38)*2)*C38-(2*2.8*F38*C38) -> 44.28 | S38: =((D38*$F$27*2)*(E38+$F$27*2))*$E$24*C38 -> 1.10565 | T38: =((D38+0.3*2)*(E38+0.3*2))*C38*AD38 -> 200.0862 | U38: =+S38/0.1 -> 11.0565 | Z38: =(D38+E38)*2*$E$24*C38 -> 8.28 | AB38: =AVERAGE(102.252,102.665) -> 102.4585 | AC38: 100.4 | AD38: =AB38-AC38 -> 2.0585
A39: =A38+1 -> 9 | B39: F-07 | C39: 1 | D39: 5.8 | E39: 2.3 | F39: 0.75 | G39: =+E39 -> 2.3 | Q39: =C39*D39*F39*G39 -> 10.005 | R39: =((D39*F39*2+E39*F39))*C39 -> 10.425 | S39: =((D39*$F$27*2)*(E39+$F$27*2))*$E$24*C39 -> 0.21315 | T39: =((D39+0.3*2)*(E39+0.3*2))*C39*AD39 -> 38.20576 | U39: =+S39/0.1 -> 2.1315 | Z39: =(D39+E39)*2*$E$24*C39 -> 1.62 | AB39: =AVERAGE(102.252,102.665) -> 102.4585 | AC39: 100.4 | AD39: =AB39-AC39 -> 2.0585
A40: =A39+1 -> 10 | B40: CF-01-PL | C40: 1 | D40: 55.198829 | E40: 33.799658 | F40: 1 | G40: =+E40 -> 33.799658 | Q40: =C40*D40*F40 -> 55.198829 | R40: =C40*E40*F40 -> 33.799658 | S40: =34.399658*E24*C40 -> 3.4399658 | T40: =((D40)*C40*AD40) -> 248.94672 | U40: =+S40/0.1 -> 34.399658 | Z40: =(D40+E40)*2*$E$24*C40 -> 17.799697 | AB40: =AVERAGE(98.5,102.252,101.078) -> 100.61 | AC40: 96.1 | AD40: =AB40-AC40 -> 4.51
A41: =A40+1 -> 11 | B41: CF-02 | C41: 1 | D41: 6.35 | E41: 2.7 | F41: 0.9 | G41: =+E41 -> 2.7 | Q41: =C41*D41*F41*G41 -> 15.4305 | R41: =((D41*F41+E41*F41)*2)*C41-(2.8*F41) -> 13.77 | S41: =((D41*$F$27*2)*(E41+$F$27*2))*$E$24*C41 -> 0.2714625 | T41: =((D41+0.3*2)*(E41+0.3*2))*C41*AD41 -> 15.54993 | U41: =+S41/0.1 -> 2.714625 | Z41: =(D41+E41)*2*$E$24*C41 -> 1.81 | AB41: 101.078 | AC41: 100.4 | AD41: =AB41-AC41 -> 0.678

Sheet Columns
B2: Floor Levels | C2: Height | D2: Concrete Qty | E2: Shuttering Qty
B3: Footing top to LGF | C3: - | D3: =G31 -> 39.151 | E3: =H31 -> 334.41
B4: LGF-GF | C4: =106.2-102 -> 4.2 | D4: =G52 -> 47.208 | E4: =H52 -> 405.72
B5: GF-FF | C5: =110.7-106.2 -> 4.5 | D5: =G72 -> 43.11 | E5: =H72 -> 400.5
B6: FF-TF | C6: =114.3-110.7 -> 3.6 | D6: =G91 -> 34.488 | E6: =H91 -> 320.4
B7: TF-OHT Level | C7: =117.2-114.3 -> 2.9 | D7: =G102 -> 9.338 | E7: =H102 -> 89.32
B8: TOTAL | D8: =SUM(D3:D7) -> 173.295 | E8: =SUM(E3:E7) -> 1550.35
B10: Footing top to LGF
A11: S.No | B11: Description | C11: Nos | D11: Length | E11: Breadth | F11: Depth | G11: Concrete Qty | H11: Shuttering Qty | M11: =G31+G52+G72+G91+G102 -> 173.295 | N11: =H31+H52+H72+H91+H102 -> 1550.35
A12: 1 | B12: C1 | C12: 3 | D12: 1.2 | E12: 0.3 | F12: =(102-100.4) -> 1.6 | G12: =C12*(D12*E12*F12) -> 1.728 | H12: =C12*(D12+E12)*2*F12 -> 14.4
A13: 2 | B13: C1A | C13: 3 | D13: 1.2 | E13: 0.3 | F13: =(102-100.4) -> 1.6 | G13: =C13*(D13*E13*F13) -> 1.728 | H13: =C13*(D13+E13)*2*F13 -> 14.4
A14: 3 | B14: C1B | C14: 2 | D14: 1.2 | E14: 0.3 | F14: =(102-100.4) -> 1.6 | G14: =C14*(D14*E14*F14) -> 1.152 | H14: =C14*(D14+E14)*2*F14 -> 9.6
A15: 4 | B15: C2 | C15: 1 | D15: 1.4 | E15: 0.3 | F15: =(102-100.4) -> 1.6 | G15: =C15*(D15*E15*F15) -> 0.672 | H15: =C15*(D15+E15)*2*F15 -> 5.44
A16: 5 | B16: C3 | C16: 1 | D16: 1.4 | E16: 0.3 | F16: =(102-100.4) -> 1.6 | G16: =C16*(D16*E16*F16) -> 0.672 | H16: =C16*(D16+E16)*2*F16 -> 5.44
A17: 6 | B17: C4 | C17: 1 | D17: 1.4 | E17: 0.3 | F17: =(102-96) -> 6 | G17: =C17*(D17*E17*F17) -> 2.52 | H17: =C17*(D17+E17)*2*F17 -> 20.4
A18: 7 | B18: C5 | C18: 1 | D18: 1.4 | E18: 0.3 | F18: =(102-96.1) -> 5.9 | G18: =C18*(D18*E18*F18) -> 2.478 | H18: =C18*(D18+E18)*2*F18 -> 20.06
B19: C5 | C19: 1 | D19: 1.4 | E19: 0.3 | F19: =(102-96.9) -> 5.1 | G19: =C19*(D19*E19*F19) -> 2.142 | H19: =C19*(D19+E19)*2*F19 -> 17.34 | L19: =101.5-1 -> 100.5
A20: 8 | B20: C6 | C20: 1 | D20: 1 | E20: 0.2 | F20: =(102-96.1) -> 5.9 | G20: =C20*(D20*E20*F20) -> 1.18 | H20: =C20*(D20+E20)*2*F20 -> 14.16
A21: 9 | B21: C7 | C21: 2 | D21: 1.4 | E21: 0.3 | F21: =(102-100.4) -> 1.6 | G21: =C21*(D21*E21*F21) -> 1.344 | H21: =C21*(D21+E21)*2*F21 -> 10.88
A22: 10 | B22: C8 | C22: 1 | D22: 1.4 | E22: 0.3 | F22: =(102-100.4) -> 1.6 | G22: =C22*(D22*E22*F22) -> 0.672 | H22: =C22*(D22+E22)*2*F22 -> 5.44
A23: 11 | B23: C9 | C23: 1 | D23: 1 | E23: 0.3 | F23: =(102-100.4) -> 1.6 | G23: =C23*(D23*E23*F23) -> 0.48 | H23: =C23*(D23+E23)*2*F23 -> 4.16
A24: 12 | B24: C10 | C24: 2 | D24: 1 | E24: 0.3 | F24: =(102-100.4) -> 1.6 | G24: =C24*(D24*E24*F24) -> 0.96 | H24: =C24*(D24+E24)*2*F24 -> 8.32
A25: 13 | B25: C11 | C25: 2 | D25: 1.2 | E25: 0.3 | F25: =(102-96.25) -> 5.75 | G25: =C25*(D25*E25*F25) -> 4.14 | H25: =C25*(D25+E25)*2*F25 -> 34.5
A26: 14 | B26: C13 | C26: 1 | D26: 1.2 | E26: 0.3 | F26: =(102-96.25) -> 5.75 | G26: =C26*(D26*E26*F26) -> 2.07 | H26: =C26*(D26+E26)*2*F26 -> 17.25
A27: 15 | B27: C14 | C27: 1 | D27: 1.2 | E27: 0.3 | F27: =(102-96.1) -> 5.9 | G27: =C27*(D27*E27*F27) -> 2.124 | H27: =C27*(D27+E27)*2*F27 -> 17.7
B28: C14 | C28: 4 | D28: 1.2 | E28: 0.3 | F28: =(102-98.6) -> 3.4 | G28: =C28*(D28*E28*F28) -> 4.896 | H28: =C28*(D28+E28)*2*F28 -> 40.8
A29: 16 | B29: C15 | C29: 1 | D29: 2.6 | E29: 0.3 | F29: =(102-96.1) -> 5.9 | G29: =C29*(D29*E29*F29) -> 4.602 | H29: =C29*(D29+E29)*2*F29 -> 34.22
A30: 17 | B30: C16 | C30: 4 | D30: 0.45 | E30: 0.3 | F30: =(102-95.35) -> 6.65 | G30: =C30*(D30*E30*F30) -> 3.591 | H30: =C30*(D30+E30)*2*F30 -> 39.9
B31: TOTAL | G31: =SUM(G12:G30) -> 39.151 | H31: =SUM(H12:H30) -> 334.41 | K31: =G31/F12*C3 -> #VALUE!
B33: LGF-GF
A34: S.No | B34: Description | C34: Nos | D34: Length | E34: Breadth | F34: Depth | G34: Concrete Qty | H34: Shuttering Qty
A35: 1 | B35: C1 | C35: 3 | D35: 1.2 | E35: 0.3 | F35: =$C$4 -> 4.2 | G35: =C35*(D35*E35*F35) -> 4.536 | H35: =C35*(D35+E35)*2*F35 -> 37.8
A36: 2 | B36: C1A | C36: 3 | D36: 1.2 | E36: 0.3 | F36: =$C$4 -> 4.2 | G36: =C36*(D36*E36*F36) -> 4.536 | H36: =C36*(D36+E36)*2*F36 -> 37.8
A37: 3 | B37: C1B | C37: 2 | D37: 1.2 | E37: 0.3 | F37: =$C$4 -> 4.2 | G37: =C37*(D37*E37*F37) -> 3.024 | H37: =C37*(D37+E37)*2*F37 -> 25.2
A38: 4 | B38: C2 | C38: 1 | D38: 1.4 | E38: 0.3 | F38: =$C$4 -> 4.2 | G38: =C38*(D38*E38*F38) -> 1.764 | H38: =C38*(D38+E38)*2*F38 -> 14.28
A39: 5 | B39: C3 | C39: 1 | D39: 1.4 | E39: 0.3 | F39: =$C$4 -> 4.2 | G39: =C39*(D39*E39*F39) -> 1.764 | H39: =C39*(D39+E39)*2*F39 -> 14.28
A40: 6 | B40: C4 | C40: 1 | D40: 1.4 | E40: 0.3 | F40: =$C$4 -> 4.2 | G40: =C40*(D40*E40*F40) -> 1.764 | H40: =C40*(D40+E40)*2*F40 -> 14.28
A41: 7 | B41: C5 | C41: 2 | D41: 1.4 | E41: 0.3 | F41: =$C$4 -> 4.2 | G41: =C41*(D41*E41*F41) -> 3.528 | H41: =C41*(D41+E41)*2*F41 -> 28.56
A42: 8 | B42: C6 | C42: 1 | D42: 1 | E42: 0.2 | F42: =$C$4 -> 4.2 | G42: =C42*(D42*E42*F42) -> 0.84 | H42: =C42*(D42+E42)*2*F42 -> 10.08
A43: 9 | B43: C7 | C43: 2 | D43: 1.4 | E43: 0.3 | F43: =$C$4 -> 4.2 | G43: =C43*(D43*E43*F43) -> 3.528 | H43: =C43*(D43+E43)*2*F43 -> 28.56
...

Sheet Beams
B1: Sl No | C1: Desc | D1: Nos | E1: L | F1: B | G1: D | H1: Concrete | I1: Bottom Shuttering | J1: Side Total | K1: Slab tk | L1: d(m) | M1: qty(m2) | N1: Slab tk | O1: d(m) | P1: qty(m2) | Q1: Column left | R1: Column right | S1: Qty | T1: Beam | U1: Beam | V1: Beam | W1: Beam | X1: Beam | Y1: Beam | Z1: Area | AC1: Sunken Depth | AD1: Sunken Depth | AJ1: 1 | AK1: 2 | AL1: 3 | AM1: 4 | AN1: 5 | AO1: 6 | AP1: 7 | AQ1: 8 | AR1: 9 | AS1: 10 | AT1: 11 | AV1: 1 | AW1: 2 | AX1: 3 | AY1: 4 | AZ1: 5 | BA1: 6 | BB1: 7 | BC1: 8 | BD1: 9 | BE1: 10 | BF1: 11 | BH1: 1 | BI1: 2 | BJ1: 3 | BK1: 4 | BL1: 5 | BM1: 6 | BN1: 7 | BO1: 8 | BP1: 9 | BQ1: 10 | BR1: 11
B2: PROJECT NAME | D2: SKECT
B3: ACTIVITY | D3: BEAMS
B6: Sl.No | C6: Description | D6: Unit | E6: =+D2 -> SKECT
E7: Quantities | P7: Total
E8: 1 | F8: 1
B9: I | C9: Concrete
C10: Plinth PCC | D10: Cum | E10: =AI153 -> 13.64334 | P10: =+SUMPRODUCT($E$8:$O$8,E10:O10) -> 13.64334
C11: Lower Ground Floor - Plinth | D11: Cum | E11: =+H153 -> 49.34946 | P11: =+SUMPRODUCT($E$8:$O$8,E11:O11) -> 49.34946
C12: Upper Ground floor | D12: Cum | E12: =H324 -> 94.551452 | P12: =+SUMPRODUCT($E$8:$O$8,E12:O12) -> 94.551452
C13: First Floor | D13: Cum | E13: =H507 -> 95.8398 | P13: =+SUMPRODUCT($E$8:$O$8,E13:O13) -> 95.8398
C14: Terrace Floor | D14: Cum | E14: =H688 -> 95.34382 | P14: =+SUMPRODUCT($E$8:$O$8,E14:O14) -> 95.34382
C15: Upper Terrace Floor | D15: Cum | E15: =H708 -> 9.8292 | P15: =+SUMPRODUCT($E$8:$O$8,E15:O15) -> 9.8292
B17: I | C17: Shuttering | P17: =+SUMPRODUCT($E$8:$O$8,E17:O17) -> 0
C18: Lower Ground Floor - Plinth | D18: Sqm | E18: =+I153+J153 -> 292.94685 | P18: =+SUMPRODUCT($E$8:$O$8,E18:O18) -> 292.94685
C19: Upper Ground floor | D19: Sqm | E19: =I324+J324 -> 716.18571 | P19: =+SUMPRODUCT($E$8:$O$8,E19:O19) -> 716.18571
C20: First Floor | D20: Sqm | E20: =I507+J507 -> 762.2164 | P20: =+SUMPRODUCT($E$8:$O$8,E20:O20) -> 762.2164
C21: Terrace Floor | D21: Sqm | E21: =I688+J688 -> 758.1582 | P21: =+SUMPRODUCT($E$8:$O$8,E21:O21) -> 758.1582
C22: Upper Terrace Floor | D22: Sqm | E22: =I708+J708 -> 81.80375 | P22: =+SUMPRODUCT($E$8:$O$8,E22:O22) -> 81.80375
C39: PCC Offset | E39: 0.1
C40: PCC thickness | E40: 0.1
J43: Side (1+2) | K43: Side 1 | L43: Side 1 | M43: Side 1 | N43: Side 2 | O43: Side 2 | P43: Side 2 | T43: intersecting | AC43: Side 1 | AD43: Side 2
B44: Sl No | C44: Desc | D44: Nos | E44: L | F44: B | G44: D | H44: Concrete | I44: Bottom Shuttering | J44: Side Total | K44: Slab tk | L44: d(m) | M44: qty(m2) | N44: Slab tk | O44: d(m) | P44: qty(m2) | Q44: Column left | R44: Column right | S44: Qty | T44: Beam | U44: Beam | V44: Beam | W44: Beam | X44: Beam | Y44: Beam | Z44: Area | AC44: Sunken Depth
A45: Lower Ground Floor Beam | AE45: tower | AG45: Podium | AI45: PCC
AE46: D<0.60 | AF46: D>0.60 | AG46: D<0.60 | AH46: D>0.60
B47: 1 | C47: PB1 | D47: 1 | E47: 6.55 | F47: 0.3 | G47: 0.6 | H47: =+PRODUCT(D47:G47) -> 1.179 | I47: =PRODUCT(D47,E47,F47)*0 -> 0 | J47: =+M47+P47 -> 5.40375 | K47: 0.2 | L47: =+G47-K47 -> 0.4 | M47: =+PRODUCT(D47,E47,L47) -> 2.62 | N47: 0.175 | O47: =+G47-N47 -> 0.425 | P47: =+PRODUCT(D47:E47,O47) -> 2.78375 | S47: =+SUM(Q47:R47)*(L47+O47)/2*2 -> 0 | Z47: =IFERROR(VLOOKUP(T47,$C$47:$G$688,4,FALSE)*VLOOKUP(T47,$C$47:$G$688,5,FALSE),)+IFERROR(VLOOKUP(U47,$C$47:$G$688,4,FALSE)*VLOOKUP(U47,$C$47:$G$688,5,FALSE),)+IFERROR(VLOOKUP(V47,$C$47:$G$9916,4,FALSE)*VLOOKUP(V47,$C$47:$G$688,5,FALSE),)+IFERROR(VLOOKUP(W47,$C$47:$G$688,4,FALSE)*VLOOKUP(W47,$C$47:$G$688,5,FALSE),)+IFERROR(VLOOKUP(X47,$C$47:$G$688,4,FALSE)*VLOOKUP(X47,$C$47:$G$688,5,FALSE),)+IFERROR(VLOOKUP(Y47,$C$47:$G$688,4,FALSE)*VLOOKUP(Y47,$C$47:$G$688,5,FALSE),) -> 0 | AE47: =+IF(G47<0.75,(I47+J47),0) -> 5.40375 | AF47: =+IF(G47<0.75,0,(I47+J47)) -> 0 | AI47: =D47*(E47*(F47+$E$39*2)*$E$40) -> 0.3275
B48: 2 | C48: PB2 | D48: 1 | E48: 6.648 | F48: 0.3 | G48: 0.6 | H48: =+PRODUCT(D48:G48) -> 1.19664 | I48: =PRODUCT(D48,E48,F48)*0 -> 0 | J48: =+M48+P48 -> 5.4846 | K48: 0.2 | L48: =+G48-K48 -> 0.4 | M48: =+PRODUCT(D48,E48,L48) -> 2.6592 | N48: 0.175 | O48: =+G48-N48 -> 0.425 | P48: =+PRODUCT(D48:E48,O48) -> 2.8254 | S48: =+SUM(Q48:R48)*(L48+O48)/2*2 -> 0 | Z48: =IFERROR(VLOOKUP(T48,$C$47:$G$688,4,FALSE)*VLOOKUP(T48,$C$47:$G$688,5,FALSE),)+IFERROR(VLOOKUP(U48,$C$47:$G$688,4,FALSE)*VLOOKUP(U48,$C$47:$G$688,5,FALSE),)+IFERROR(VLOOKUP(V48,$C$47:$G$9916,4,FALSE)*VLOOKUP(V48,$C$47:$G$688,5,FALSE),)+IFERROR(VLOOKUP(W48,$C$47:$G$688,4,FALSE)*VLOOKUP(W48,$C$47:$G$688,5,FALSE),)+IFERROR(VLOOKUP(X48,$C$47:$G$688,4,FALSE)*VLOOKUP(X48,$C$47:$G$688,5,FALSE),)+IFERROR(VLOOKUP(Y48,$C$47:$G$688,4,FALSE)*VLOOKUP(Y48,$C$47:$G$688,5,FALSE),) -> 0 | AE48: =+IF(G48<0.75,(I48+J48),0) -> 5.4846 | AF48: =+IF(G48<0.75,0,(I48+J48)) -> 0 | AI48: =D48*(E48*(F48+$E$39*2)*$E$40) -> 0.3324
B49: 3 | C49: PB3 | D49: 1 | E49: 2 | F49: 0.3 | G49: 0.6 | H49: =+PRODUCT(D49:G49) -> 0.36 | I49: =PRODUCT(D49,E49,F49)*0 -> 0 | J49: =+M49+P49 -> 1.7 | K49: 0.2 | L49: =+G49-K49 -> 0.4 | M49: =+PRODUCT(D49,E49,L49) -> 0.8 | N49: 0.15 | O49: =+G49-N49 -> 0.45 | P49: =+PRODUCT(D49:E49,O49) -> 0.9 | S49: =+SUM(Q49:R49)*(L49+O49)/2*2 -> 0 | Z49: =IFERROR(VLOOKUP(T49,$C$47:$G$688,4,FALSE)*VLOOKUP(T49,$C$47:$G$688,5,FALSE),)+IFERROR(VLOOKUP(U49,$C$47:$G$688,4,FALSE)*VLOOKUP(U49,$C$47:$G$688,5,FALSE),)+IFERROR(VLOOKUP(V49,$C$47:$G$9916,4,FALSE)*VLOOKUP(V49,$C$47:$G$688,5,FALSE),)+IFERROR(VLOOKUP(W49,$C$47:$G$688,4,FALSE)*VLOOKUP(W49,$C$47:$G$688,5,FALSE),)+IFERROR(VLOOKUP(X49,$C$47:$G$688,4,FALSE)*VLOOKUP(X49,$C$47:$G$688,5,FALSE),)+IFERROR(VLOOKUP(Y49,$C$47:$G$688,4,FALSE)*VLOOKUP(Y49,$C$47:$G$688,5,FALSE),) -> 0 | AE49: =+IF(G49<0.75,(I49+J49),0) -> 1.7 | AF49: =+IF(G49<0.75,0,(I49+J49)) -> 0 | AI49: =D49*(E49*(F49+$E$39*2)*$E$40) -> 0.1
B50: 4 | C50: PB4 | D50: 1 | E50: 4.323 | F50: 0.3 | G50: 0.6 | H50: =+PRODUCT(D50:G50) -> 0.77814 | I50: =PRODUCT(D50,E50,F50)*0 -> 0 | J50: =+M50+P50 -> 3.566475 | K50: 0.2 | L50: =+G50-K50 -> 0.4 | M50: =+PRODUCT(D50,E50,L50) -> 1.7292 | N50: 0.175 | O50: =+G50-N50 -> 0.425 | P50: =+PRODUCT(D50:E50,O50) -> 1.837275 | S50: =+SUM(Q50:R50)*(L50+O50)/2*2 -> 0 | Z50: =IFERROR(VLOOKUP(T50,$C$47:$G$688,4,FALSE)*VLOOKUP(T50,$C$47:$G$688,5,FALSE),)+IFERROR(VLOOKUP(U50,$C$47:$G$688,4,FALSE)*VLOOKUP(U50,$C$47:$G$688,5,FALSE),)+IFERROR(VLOOKUP(V50,$C$47:$G$9916,4,FALSE)*VLOOKUP(V50,$C$47:$G$688,5,FALSE),)+IFERROR(VLOOKUP(W50,$C$47:$G$688,4,FALSE)*VLOOKUP(W50,$C$47:$G$688,5,FALSE),)+IFERROR(VLOOKUP(X50,$C$47:$G$688,4,FALSE)*VLOOKUP(X50,$C$47:$G$688,5,FALSE),)+IFERROR(VLOOKUP(Y50,$C$47:$G$688,4,FALSE)*VLOOKUP(Y50,$C$47:$G$688,5,FALSE),) -> 0 | AE50: =+IF(G50<0.75,(I50+J50),0) -> 3.566475 | AF50: =+IF(G50<0.75,0,(I50+J50)) -> 0 | AI50: =D50*(E50*(F50+$E$39*2)*$E$40) -> 0.21615
B51: 5 | C51: PB5 | D51: 1 | E51: 6.55 | F51: 0.3 | G51: 0.6 | H51: =+PRODUCT(D51:G51) -> 1.179 | I51: =PRODUCT(D51,E51,F51)*0 -> 0 | J51: =+M51+P51 -> 5.73125 | K51: 0.2 | L51: =+G51-K51 -> 0.4 | M51: =+PRODUCT(D51,E51,L51) -> 2.62 | N51: 0.125 | O51: =+G51-N51 -> 0.475 | P51: =+PRODUCT(D51:E51,O51) -> 3.11125 | S51: =+SUM(Q51:R51)*(L51+O51)/2*2 -> 0 | Z51: =IFERROR(VLOOKUP(T51,$C$47:$G$688,4,FALSE)*VLOOKUP(T51,$C$47:$G$688,5,FALSE),)+IFERROR(VLOOKUP(U51,$C$47:$G$688,4,FALSE)*VLOOKUP(U51,$C$47:$G$688,5,FALSE),)+IFERROR(VLOOKUP(V51,$C$47:$G$9916,4,FALSE)*VLOOKUP(V51,$C$47:$G$688,5,FALSE),)+IFERROR(VLOOKUP(W51,$C$47:$G$688,4,FALSE)*VLOOKUP(W51,$C$47:$G$688,5,FALSE),)+IFERROR(VLOOKUP(X51,$C$47:$G$688,4,FALSE)*VLOOKUP(X51,$C$47:$G$688,5,FALSE),)+IFERROR(VLOOKUP(Y51,$C$47:$G$688,4,FALSE)*VLOOKUP(Y51,$C$47:$G$688,5,FALSE),) -> 0 | AE51: =+IF(G51<0.75,(I51+J51),0) -> 5.73125 | AF51: =+IF(G51<0.75,0,(I51+J51)) -> 0 | AI51: =D51*(E51*(F51+$E$39*2)*$E$40) -> 0.3275
B52: 6 | C52: PB6 | D52: 1 | E52: 6.599 | F52: 0.3 | G52: 0.6 | H52: =+PRODUCT(D52:G52) -> 1.18782 | I52: =PRODUCT(D52,E52,F52)*0 -> 0 | J52: =+M52+P52 -> 5.444175 | K52: 0.2 | L52: =+G52-K52 -> 0.4 | M52: =+PRODUCT(D52,E52,L52) -> 2.6396 | N52: 0.175 | O52: =+G52-N52 -> 0.425 | P52: =+PRODUCT(D52:E52,O52) -> 2.804575 | S52: =+SUM(Q52:R52)*(L52+O52)/2*2 -> 0 | Z52: =IFERROR(VLOOKUP(T52,$C$47:$G$688,4,FALSE)*VLOOKUP(T52,$C$47:$G$688,5,FALSE),)+IFERROR(VLOOKUP(U52,$C$47:$G$688,4,FALSE)*VLOOKUP(U52,$C$47:$G$688,5,FALSE),)+IFERROR(VLOOKUP(V52,$C$47:$G$9916,4,FALSE)*VLOOKUP(V52,$C$47:$G$688,5,FALSE),)+IFERROR(VLOOKUP(W52,$C$47:$G$688,4,FALSE)*VLOOKUP(W52,$C$47:$G$688,5,FALSE),)+IFERROR(VLOOKUP(X52,$C$47:$G$688,4,FALSE)*VLOOKUP(X52,$C$47:$G$688,5,FALSE),)+IFERROR(VLOOKUP(Y52,$C$47:$G$688,4,FALSE)*VLOOKUP(Y52,$C$47:$G$688,5,FALSE),) -> 0 | AE52: =+IF(G52<0.75,(I52+J52),0) -> 5.444175 | AF52: =+IF(G52<0.75,0,(I52+J52)) -> 0 | AI52: =D52*(E52*(F52+$E$39*2)*$E$40) -> 0.32995
B53: 7 | C53: PB7 | D53: 1 | E53: 6.652 | F53: 0.3 | G53: 0.6 | H53: =+PRODUCT(D53:G53) -> 1.19736 | I53: =PRODUCT(D53,E53,F53)*0 -> 0 | J53: =+M53+P53 -> 5.4879 | K53: 0.2 | L53: =+G53-K53 -> 0.4 | M53: =+PRODUCT(D53,E53,L53) -> 2.6608 | N53: 0.175 | O53: =+G53-N53 -> 0.425 | P53: =+PRODUCT(D53:E53,O53) -> 2.8271 | S53: =+SUM(Q53:R53)*(L53+O53)/2*2 -> 0 | T53: PB32A | Z53: =IFERROR(VLOOKUP(T53,$C$47:$G$688,4,FALSE)*VLOOKUP(T53,$C$47:$G$688,5,FALSE),)+IFERROR(VLOOKUP(U53,$C$47:$G$688,4,FALSE)*VLOOKUP(U53,$C$47:$G$688,5,FALSE),)+IFERROR(VLOOKUP(V53,$C$47:$G$9916,4,FALSE)*VLOOKUP(V53,$C$47:$G$688,5,FALSE),)+IFERROR(VLOOKUP(W53,$C$47:$G$688,4,FALSE)*VLOOKUP(W53,$C$47:$G$688,5,FALSE),)+IFERROR(VLOOKUP(X53,$C$47:$G$688,4,FALSE)*VLOOKUP(X53,$C$47:$G$688,5,FALSE),)+IFERROR(VLOOKUP(Y53,$C$47:$G$688,4,FALSE)*VLOOKUP(Y53,$C$47:$G$688,5,FALSE),) -> 0.12 | AE53: =+IF(G53<0.75,(I53+J53),0) -> 5.4879 | AF53: =+IF(G53<0.75,0,(I53+J53)) -> 0 | AI53: =D53*(E53*(F53+$E$39*2)*$E$40) -> 0.3326
B54: 8 | C54: PB8 | D54: 1 | E54: 6.55 | F54: 0.3 | G54: 0.8 | H54: =+PRODUCT(D54:G54) -> 1.572 | I54: =PRODUCT(D54,E54,F54)*0 -> 0 | J54: =+M54+P54 -> 8.02375 | K54: 0.175 | L54: =+G54-K54 -> 0.625 | M54: =+PRODUCT(D54,E54,L54) -> 4.09375 | N54: 0.2 | O54: =+G54-N54 -> 0.6 | P54: =+PRODUCT(D54:E54,O54) -> 3.93 | S54: =+SUM(Q54:R54)*(L54+O54)/2*2 -> 0 | T54: BR35 | U54: BR36 | Z54: =IFERROR(VLOOKUP(T54,$C$47:$G$688,4,FALSE)*VLOOKUP(T54,$C$47:$G$688,5,FALSE),)+IFERROR(VLOOKUP(U54,$C$47:$G$688,4,FALSE)*VLOOKUP(U54,$C$47:$G$688,5,FALSE),)+IFERROR(VLOOKUP(V54,$C$47:$G$9916,4,FALSE)*VLOOKUP(V54,$C$47:$G$688,5,FALSE),)+IFERROR(VLOOKUP(W54,$C$47:$G$688,4,FALSE)*VLOOKUP(W54,$C$47:$G$688,5,FALSE),)+IFERROR(VLOOKUP(X54,$C$47:$G$688,4,FALSE)*VLOOKUP(X54,$C$47:$G$688,5,FALSE),)+IFERROR(VLOOKUP(Y54,$C$47:$G$688,4,FALSE)*VLOOKUP(Y54,$C$47:$G$688,5,FALSE),) -> 0.24 | AE54: =+IF(G54<0.75,(I54+J54),0) -> 0 | AF54: =+IF(G54<0.75,0,(I54+J54)) -> 8.02375 | AI54: =D54*(E54*(F54+$E$39*2)*$E$40) -> 0.3275
B55: 9 | C55: PB9 | D55: 1 | E55: 6.648 | F55: 0.3 | G55: 0.6 | H55: =+PRODUCT(D55:G55) -> 1.19664 | I55: =PRODUCT(D55,E55,F55)*0 -> 0 | J55: =+M55+P55 -> 6.8142 | K55: 0.175 | L55: =+G55-K55 -> 0.425 | M55: =+PRODUCT(D55,E55,L55) -> 2.8254 | N55: 0 | O55: =+G55-N55 -> 0.6 | P55: =+PRODUCT(D55:E55,O55) -> 3.9888 | S55: =+SUM(Q55:R55)*(L55+O55)/2*2 -> 0 | T55: BR39 | U55: BR40 | V55: BR41 | Z55: =IFERROR(VLOOKUP(T55,$C$47:$G$688,4,FALSE)*VLOOKUP(T55,$C$47:$G$688,5,FALSE),)+IFERROR(VLOOKUP(U55,$C$47:$G$688,4,FALSE)*VLOOKUP(U55,$C$47:$G$688,5,FALSE),)+IFERROR(VLOOKUP(V55,$C$47:$G$9916,4,FALSE)*VLOOKUP(V55,$C$47:$G$688,5,FALSE),)+IFERROR(VLOOKUP(W55,$C$47:$G$688,4,FALSE)*VLOOKUP(W55,$C$47:$G$688,5,FALSE),)+IFERROR(VLOOKUP(X55,$C$47:$G$688,4,FALSE)*VLOOKUP(X55,$C$47:$G$688,5,FALSE),)+IFERROR(VLOOKUP(Y55,$C$47:$G$688,4,FALSE)*VLOOKUP(Y55,$C$47:$G$688,5,FALSE),) -> 0.36 | AE55: =+IF(G55<0.75,(I55+J55),0) -> 6.8142 | AF55: =+IF(G55<0.75,0,(I55+J55)) -> 0 | AI55: =D55*(E55*(F55+$E$39*2)*$E$40) -> 0.3324
B56: 10 | C56: PB10 | D56: 1 | E56: 5.475 | F56: 0.3 | G56: 0.8 | H56: =+PRODUCT(D56:G56) -> 1.314 | I56: =PRODUCT(D56,E56,F56)*0 -> 0 | J56: =+M56+P56 -> 7.801875 | K56: 0.175 | L56: =+G56-K56 -> 0.625 | M56: =+PRODUCT(D56,E56,L56) -> 3.421875 | N56: 0 | O56: =+G56-N56 -> 0.8 | P56: =+PRODUCT(D56:E56,O56) -> 4.38 | S56: =+SUM(Q56:R56)*(L56+O56)/2*2 -> 0 | Z56: =IFERROR(VLOOKUP(T56,$C$47:$G$688,4,FALSE)*VLOOKUP(T56,$C$47:$G$688,5,FALSE),)+IFERROR(VLOOKUP(U56,$C$47:$G$688,4,FALSE)*VLOOKUP(U56,$C$47:$G$688,5,FALSE),)+IFERROR(VLOOKUP(V56,$C$47:$G$9916,4,FALSE)*VLOOKUP(V56,$C$47:$G$688,5,FALSE),)+IFERROR(VLOOKUP(W56,$C$47:$G$688,4,FALSE)*VLOOKUP(W56,$C$47:$G$688,5,FALSE),)+IFERROR(VLOOKUP(X56,$C$47:$G$688,4,FALSE)*VLOOKUP(X56,$C$47:$G$688,5,FALSE),)+IFERROR(VLOOKUP(Y56,$C$47:$G$688,4,FALSE)*VLOOKUP(Y56,$C$47:$G$688,5,FALSE),) -> 0 | AE56: =+IF(G56<0.75,(I56+J56),0) -> 0 | AF56: =+IF(G56<0.75,0,(I56+J56)) -> 7.801875 | AI56: =D56*(E56*(F56+$E$39*2)*$E$40) -> 0.27375
B57: 11 | C57: PB11 | D57: 1 | E57: 6.552 | F57: 0.3 | G57: 0.8 | H57: =+PRODUCT(D57:G57) -> 1.57248 | I57: =PRODUCT(D57,E57,F57)*0 -> 0 | J57: =+M57+P57 -> 8.6814 | K57: 0.15 | L57: =+G57-K57 -> 0.65 | M57: =+PRODUCT(D57,E57,L57) -> 4.2588 | N57: 0.125 | O57: =+G57-N57 -> 0.675 | P57: =+PRODUCT(D57:E57,O57) -> 4.4226 | S57: =+SUM(Q57:R57)*(L57+O57)/2*2 -> 0 | T57: BR48 | U57: BR49 | V57: BR50 | W57: PB27 | Z57: =IFERROR(VLOOKUP(T57,$C$47:$G$688,4,FALSE)*VLOOKUP(T57,$C$47:$G$688,5,FALSE),)+IFERROR(VLOOKUP(U57,$C$47:$G$688,4,FALSE)*VLOOKUP(U57,$C$47:$G$688,5,FALSE),)+IFERROR(VLOOKUP(V57,$C$47:$G$9916,4,FALSE)*VLOOKUP(V57,$C$47:$G$688,5,FALSE),)+IFERROR(VLOOKUP(W57,$C$47:$G$688,4,FALSE)*VLOOKUP(W57,$C$47:$G$688,5,FALSE),)+IFERROR(VLOOKUP(X57,$C$47:$G$688,4,FALSE)*VLOOKUP(X57,$C$47:$G$688,5,FALSE),)+IFERROR(VLOOKUP(Y57,$C$47:$G$688,4,FALSE)*VLOOKUP(Y57,$C$47:$G$688,5,FALSE),) -> 0.54 | AE57: =+IF(G57<0.75,(I57+J57),0) -> 0 | AF57: =+IF(G57<0.75,0,(I57+J57)) -> 8.6814 | AI57: =D57*(E57*(F57+$E$39*2)*$E$40) -> 0.3276
B58: 12 | C58: PB12 | D58: 1 | E58: 6.598 | F58: 0.3 | G58: 0.8 | H58: =+PRODUCT(D58:G58) -> 1.58352 | I58: =PRODUCT(D58,E58,F58)*0 -> 0 | J58: =+M58+P58 -> 8.08255 | K58: 0.175 | L58: =+G58-K58 -> 0.625 | M58: =+PRODUCT(D58,E58,L58) -> 4.12375 | N58: 0.2 | O58: =+G58-N58 -> 0.6 | P58: =+PRODUCT(D58:E58,O58) -> 3.9588 | S58: =+SUM(Q58:R58)*(L58+O58)/2*2 -> 0 | T58: BR52 | U58: BR53 | V58: BR54 | Z58: =IFERROR(VLOOKUP(T58,$C$47:$G$688,4,FALSE)*VLOOKUP(T58,$C$47:$G$688,5,FALSE),)+IFERROR(VLOOKUP(U58,$C$47:$G$688,4,FALSE)*VLOOKUP(U58,$C$47:$G$688,5,FALSE),)+IFERROR(VLOOKUP(V58,$C$47:$G$9916,4,FALSE)*VLOOKUP(V58,$C$47:$G$688,5,FALSE),)+IFERROR(VLOOKUP(W58,$C$47:$G$688,4,FALSE)*VLOOKUP(W58,$C$47:$G$688,5,FALSE),)+IFERROR(VLOOKUP(X58,$C$47:$G$688,4,FALSE)*VLOOKUP(X58,$C$47:$G$688,5,FALSE),)+IFERROR(VLOOKUP(Y58,$C$47:$G$688,4,FALSE)*VLOOKUP(Y58,$C$47:$G$688,5,FALSE),) -> 0.36 | AE58: =+IF(G58<0.75,(I58+J58),0) -> 0 | AF58: =+IF(G58<0.75,0,(I58+J58)) -> 8.08255 | AI58: =D58*(E58*(F58+$E$39*2)*$E$40) -> 0.3299
B59: 13 | C59: PB13 | D59: 1 | E59: 6.519 | F59: 0.3 | G59: 0.8 | H59: =+PRODUCT(D59:G59) -> 1.56456 | I59: =PRODUCT(D59,E59,F59)*0 -> 0 | J59: =+M59+P59 -> 8.4747 | K59: 0.175 | L59: =+G59-K59 -> 0.625 | M59: =+PRODUCT(D59,E59,L59) -> 4.074375 | N59: 0.125 | O59: =+G59-N59 -> 0.675 | P59: =+PRODUCT(D59:E59,O59) -> 4.400325 | S59: =+SUM(Q59:R59)*(L59+O59)/2*2 -> 0 | T59: PB32 | U59: BR56 | V59: PB32A | Z59: =IFERROR(VLOOKUP(T59,$C$47:$G$688,4,FALSE)*VLOOKUP(T59,$C$47:$G$688,5,FALSE),)+IFERROR(VLOOKUP(U59,$C$47:$G$688,4,FALSE)*VLOOKUP(U59,$C$47:$G$688,5,FALSE),)+IFERROR(VLOOKUP(V59,$C$47:$G$9916,4,FALSE)*VLOOKUP(V59,$C$47:$G$688,5,FALSE),)+IFERROR(VLOOKUP(W59,$C$47:$G$688,4,FALSE)*VLOOKUP(W59,$C$47:$G$688,5,FALSE),)+IFERROR(VLOOKUP(X59,$C$47:$G$688,4,FALSE)*VLOOKUP(X59,$C$47:$G$688,5,FALSE),)+IFERROR(VLOOKUP(Y59,$C$47:$G$688,4,FALSE)*VLOOKUP(Y59,$C$47:$G$688,5,FALSE),) -> 0.36 | AE59: =+IF(G59<0.75,(I59+J59),0) -> 0 | AF59: =+IF(G59<0.75,0,(I59+J59)) -> 8.4747 | AI59: =D59*(E59*(F59+$E$39*2)*$E$40) -> 0.32595
